2023-07-10 01:57:19,058 - Thread-2 (process_request_thread) - MainProcess - ERROR - Ocurrio una excepcion:'activo'
Traceback (most recent call last):
  File "C:\Users\50431\AppData\Local\Programs\Python\Python311\Lib\site-packages\django\utils\datastructures.py", line 84, in __getitem__
    list_ = super().__getitem__(key)
            ^^^^^^^^^^^^^^^^^^^^^^^^
KeyError: 'activo'

During handling of the above exception, another exception occurred:

Traceback (most recent call last):
  File "C:\Users\50431\Desktop\ISI\ISI_2023_I_P_CLINICAMR_FRONT_DEPLOY\CLINICA\views_api\views_permisos.py", line 133, in actualizar_permisos
    activo = request.POST['activo']
             ~~~~~~~~~~~~^^^^^^^^^^
  File "C:\Users\50431\AppData\Local\Programs\Python\Python311\Lib\site-packages\django\utils\datastructures.py", line 86, in __getitem__
    raise MultiValueDictKeyError(key)
django.utils.datastructures.MultiValueDictKeyError: 'activo'
