2023-07-09 15:01:18,610 - Thread-10 (process_request_thread) - MainProcess - ERROR - Ocurrio una excepcion:'payment_method'
Traceback (most recent call last):
  File "C:\Users\50431\AppData\Local\Programs\Python\Python311\Lib\site-packages\django\utils\datastructures.py", line 84, in __getitem__
    list_ = super().__getitem__(key)
            ^^^^^^^^^^^^^^^^^^^^^^^^
KeyError: 'payment_method'

During handling of the above exception, another exception occurred:

Traceback (most recent call last):
  File "C:\Users\50431\Desktop\ISI\ISI_2023_I_P_CLINICAMR_FRONT_DEPLOY\CLINICA\views_api\views_permisos.py", line 133, in actualizar_permisos
    activo = request.POST['payment_method']
             ~~~~~~~~~~~~^^^^^^^^^^^^^^^^^^
  File "C:\Users\50431\AppData\Local\Programs\Python\Python311\Lib\site-packages\django\utils\datastructures.py", line 86, in __getitem__
    raise MultiValueDictKeyError(key)
django.utils.datastructures.MultiValueDictKeyError: 'payment_method'
