2023-07-10 02:02:54,391 - Thread-1 (process_request_thread) - MainProcess - ERROR - Ocurrio una excepcion:'id_permisos'
Traceback (most recent call last):
  File "C:\Users\50431\AppData\Local\Programs\Python\Python311\Lib\site-packages\django\utils\datastructures.py", line 84, in __getitem__
    list_ = super().__getitem__(key)
            ^^^^^^^^^^^^^^^^^^^^^^^^
KeyError: 'id_permisos'

During handling of the above exception, another exception occurred:

Traceback (most recent call last):
  File "C:\Users\50431\Desktop\ISI\ISI_2023_I_P_CLINICAMR_FRONT_DEPLOY\CLINICA\views_api\views_permisos.py", line 87, in abrir_actualizar_permisos
    resp = requests.get(url+'permisos/busqueda/id/'+str(request.POST['id_permisos']))
                                                        ~~~~~~~~~~~~^^^^^^^^^^^^^^^
  File "C:\Users\50431\AppData\Local\Programs\Python\Python311\Lib\site-packages\django\utils\datastructures.py", line 86, in __getitem__
    raise MultiValueDictKeyError(key)
django.utils.datastructures.MultiValueDictKeyError: 'id_permisos'
