2023-07-10 01:49:23,611 - Thread-1 (process_request_thread) - MainProcess - ERROR - Ocurrio una excepcion:'id_acciones'
Traceback (most recent call last):
  File "C:\Users\50431\AppData\Local\Programs\Python\Python311\Lib\site-packages\django\utils\datastructures.py", line 84, in __getitem__
    list_ = super().__getitem__(key)
            ^^^^^^^^^^^^^^^^^^^^^^^^
KeyError: 'id_acciones'

During handling of the above exception, another exception occurred:

Traceback (most recent call last):
  File "C:\Users\50431\Desktop\ISI\ISI_2023_I_P_CLINICAMR_FRONT_DEPLOY\CLINICA\views_api\views_acciones.py", line 60, in abrir_actualizar_acciones
    resp = requests.get(url+'acciones/busqueda/id/'+str(request.POST['id_acciones']))
                                                        ~~~~~~~~~~~~^^^^^^^^^^^^^^^
  File "C:\Users\50431\AppData\Local\Programs\Python\Python311\Lib\site-packages\django\utils\datastructures.py", line 86, in __getitem__
    raise MultiValueDictKeyError(key)
django.utils.datastructures.MultiValueDictKeyError: 'id_acciones'
